Workbook

Sheet REV BY GEO
A1: ADS GY Equity - Net Revenue by Reporting Region (SYNTHETIC SAMPLE)
A2: Units: EUR mn. Regional segmentation was restated with effect from FY2020; pre-FY2020 regions are not directly comparable.
A4: Region | C4: 2016 | D4: 2017 | E4: 2018 | F4: 2019 | G4: 2020 | H4: 2021 | I4: 2022 | J4: 2023
A6: REPORTED SEGMENTATION - FY2016 to FY2019
A7: Western Europe | C7: 5,452.0 | D7: 5,856.0 | E7: 5,764.0 | F7: 5,957.0 | G7: — | H7: — | I7: — | J7: —
A8: North America | C8: 3,068.0 | D8: 3,947.0 | E8: 4,361.0 | F8: 4,917.0 | G8: — | H8: — | I8: — | J8: —
A9: Grtr China | C9: 2,976.0 | D9: 3,756.0 | E9: 4,164.0 | F9: 4,728.0 | G9: — | H9: — | I9: — | J9: —
A10: Russia / CIS | C10: 721.0 | D10: 700.0 | E10: 679.0 | F10: 686.0 | G10: — | H10: — | I10: — | J10: —
A11: Latin America | C11: 1,645.0 | D11: 1,740.0 | E11: 1,688.0 | F11: 1,726.0 | G11: — | H11: — | I11: — | J11: —
A12: Other Asian Mkts | C12: 2,421.0 | D12: 2,716.0 | E12: 2,761.0 | F12: 2,931.0 | G12: — | H12: — | I12: — | J12: —
A13: Emerging Markets | C13: 1,220.0 | D13: 1,400.0 | E13: 1,512.0 | F13: 1,726.0 | G13: — | H13: — | I13: — | J13: —
A14: Other Businesses | C14: 980.0 | D14: 1,103.0 | E14: 986.0 | F14: 969.0 | G14: — | H14: — | I14: — | J14: —
A16: REPORTED SEGMENTATION - FY2020 to FY2023
A17: EMEA | C17: — | D17: — | E17: — | F17: — | G17: 7,005.0 | H17: 7,432.0 | I17: 7,879.0 | J17: 7,585.0
A18: North America | C18: — | D18: — | E18: — | F18: — | G18: 4,127.0 | H18: 5,330.0 | I18: 5,921.0 | J18: 5,142.0
A19: Greater China | C19: — | D19: — | E19: — | F19: — | G19: 4,346.0 | H19: 4,247.0 | I19: 3,534.0 | J19: 3,257.0
A20: Asia-Pacific | C20: — | D20: — | E20: — | F20: — | G20: 2,342.0 | H20: 2,060.0 | I20: 2,656.0 | J20: 2,807.0
A21: Latin America | C21: — | D21: — | E21: — | F21: — | G21: 1,310.0 | H21: 1,507.0 | I21: 1,891.0 | J21: 2,057.0
A22: Other Businesses | C22: — | D22: — | E22: — | F22: — | G22: 714.0 | H22: 658.0 | I22: 630.0 | J22: 579.0
A24: TOTAL NET REVENUE | C24: 18,483.0 | D24: 21,218.0 | E24: 21,915.0 | F24: 23,640.0 | G24: 19,844.0 | H24: 21,234.0 | I24: 22,511.0 | J24: 21,427.0
A27: Use the region mapping table on the LOOKUP TABLES sheet to build a single comparable regional view for FY2016-FY2023.
A28: SYNTHETIC SAMPLE DATA - classroom use only.

Sheet Master P&L
A1: Master P&L Analysis — EUR mn unless stated
A2: EUR mn, except per-share data
A3: Line Item | B3: FY2016 | C3: FY2017 | D3: FY2018 | E3: FY2019 | F3: FY2020 | G3: FY2021 | H3: FY2022 | I3: FY2023 | J3: Statement Group | K3: Sign Convention
A4: =Lookup!A2 -> Basic EPS | B4: =IFERROR(SUMIFS('Cleaned Data'!$C:$C,'Cleaned Data'!$A:$A,_xlfn.XLOOKUP($A4,Lookup!$A:$A,Lookup!$D:$D),'Cleaned Data'!$B:$B,B$3),"") -> 4.72 | C4: =IFERROR(SUMIFS('Cleaned Data'!$C:$C,'Cleaned Data'!$A:$A,_xlfn.XLOOKUP($A4,Lookup!$A:$A,Lookup!$D:$D),'Cleaned Data'!$B:$B,C$3),"") -> 6.78 | D4: =IFERROR(SUMIFS('Cleaned Data'!$C:$C,'Cleaned Data'!$A:$A,_xlfn.XLOOKUP($A4,Lookup!$A:$A,Lookup!$D:$D),'Cleaned Data'!$B:$B,D$3),"") -> 8.45 | E4: =IFERROR(SUMIFS('Cleaned Data'!$C:$C,'Cleaned Data'!$A:$A,_xlfn.XLOOKUP($A4,Lookup!$A:$A,Lookup!$D:$D),'Cleaned Data'!$B:$B,E$3),"") -> 9.48 | F4: =IFERROR(SUMIFS('Cleaned Data'!$C:$C,'Cleaned Data'!$A:$A,_xlfn.XLOOKUP($A4,Lookup!$A:$A,Lookup!$D:$D),'Cleaned Data'!$B:$B,F$3),"") -> 1.79 | G4: =IFERROR(SUMIFS('Cleaned Data'!$C:$C,'Cleaned Data'!$A:$A,_xlfn.XLOOKUP($A4,Lookup!$A:$A,Lookup!$D:$D),'Cleaned Data'!$B:$B,G$3),"") -> 7.39 | H4: =IFERROR(SUMIFS('Cleaned Data'!$C:$C,'Cleaned Data'!$A:$A,_xlfn.XLOOKUP($A4,Lookup!$A:$A,Lookup!$D:$D),'Cleaned Data'!$B:$B,H$3),"") -> 0.27 | I4: =IFERROR(SUMIFS('Cleaned Data'!$C:$C,'Cleaned Data'!$A:$A,_xlfn.XLOOKUP($A4,Lookup!$A:$A,Lookup!$D:$D),'Cleaned Data'!$B:$B,I$3),"") -> -0.18 | J4: =_xlfn.XLOOKUP($A4,Lookup!$A:$A,Lookup!$B:$B,"") -> EPS / Per Share | K4: =_xlfn.XLOOKUP($A4,Lookup!$A:$A,Lookup!$C:$C,"") -> Per Share
A5: =Lookup!A3 -> Cost of Goods Sold | B5: =IFERROR(SUMIFS('Cleaned Data'!$C:$C,'Cleaned Data'!$A:$A,_xlfn.XLOOKUP($A5,Lookup!$A:$A,Lookup!$D:$D),'Cleaned Data'!$B:$B,B$3),"") -> -9500 | C5: =IFERROR(SUMIFS('Cleaned Data'!$C:$C,'Cleaned Data'!$A:$A,_xlfn.XLOOKUP($A5,Lookup!$A:$A,Lookup!$D:$D),'Cleaned Data'!$B:$B,C$3),"") -> -10524 | D5: =IFERROR(SUMIFS('Cleaned Data'!$C:$C,'Cleaned Data'!$A:$A,_xlfn.XLOOKUP($A5,Lookup!$A:$A,Lookup!$D:$D),'Cleaned Data'!$B:$B,D$3),"") -> -10607 | E5: =IFERROR(SUMIFS('Cleaned Data'!$C:$C,'Cleaned Data'!$A:$A,_xlfn.XLOOKUP($A5,Lookup!$A:$A,Lookup!$D:$D),'Cleaned Data'!$B:$B,E$3),"") -> -11347 | F5: =IFERROR(SUMIFS('Cleaned Data'!$C:$C,'Cleaned Data'!$A:$A,_xlfn.XLOOKUP($A5,Lookup!$A:$A,Lookup!$D:$D),'Cleaned Data'!$B:$B,F$3),"") -> -9982 | G5: =IFERROR(SUMIFS('Cleaned Data'!$C:$C,'Cleaned Data'!$A:$A,_xlfn.XLOOKUP($A5,Lookup!$A:$A,Lookup!$D:$D),'Cleaned Data'!$B:$B,G$3),"") -> -10511 | H5: =IFERROR(SUMIFS('Cleaned Data'!$C:$C,'Cleaned Data'!$A:$A,_xlfn.XLOOKUP($A5,Lookup!$A:$A,Lookup!$D:$D),'Cleaned Data'!$B:$B,H$3),"") -> -11863 | I5: =IFERROR(SUMIFS('Cleaned Data'!$C:$C,'Cleaned Data'!$A:$A,_xlfn.XLOOKUP($A5,Lookup!$A:$A,Lookup!$D:$D),'Cleaned Data'!$B:$B,I$3),"") -> -11249 | J5: =_xlfn.XLOOKUP($A5,Lookup!$A:$A,Lookup!$B:$B,"") -> COGS | K5: =_xlfn.XLOOKUP($A5,Lookup!$A:$A,Lookup!$C:$C,"") -> Negative
A6: =Lookup!A4 -> Diluted EPS | B6: =IFERROR(SUMIFS('Cleaned Data'!$C:$C,'Cleaned Data'!$A:$A,_xlfn.XLOOKUP($A6,Lookup!$A:$A,Lookup!$D:$D),'Cleaned Data'!$B:$B,B$3),"") -> 4.7 | C6: =IFERROR(SUMIFS('Cleaned Data'!$C:$C,'Cleaned Data'!$A:$A,_xlfn.XLOOKUP($A6,Lookup!$A:$A,Lookup!$D:$D),'Cleaned Data'!$B:$B,C$3),"") -> 6.75 | D6: =IFERROR(SUMIFS('Cleaned Data'!$C:$C,'Cleaned Data'!$A:$A,_xlfn.XLOOKUP($A6,Lookup!$A:$A,Lookup!$D:$D),'Cleaned Data'!$B:$B,D$3),"") -> 8.42 | E6: =IFERROR(SUMIFS('Cleaned Data'!$C:$C,'Cleaned Data'!$A:$A,_xlfn.XLOOKUP($A6,Lookup!$A:$A,Lookup!$D:$D),'Cleaned Data'!$B:$B,E$3),"") -> 9.44 | F6: =IFERROR(SUMIFS('Cleaned Data'!$C:$C,'Cleaned Data'!$A:$A,_xlfn.XLOOKUP($A6,Lookup!$A:$A,Lookup!$D:$D),'Cleaned Data'!$B:$B,F$3),"") -> 1.78 | G6: =IFERROR(SUMIFS('Cleaned Data'!$C:$C,'Cleaned Data'!$A:$A,_xlfn.XLOOKUP($A6,Lookup!$A:$A,Lookup!$D:$D),'Cleaned Data'!$B:$B,G$3),"") -> 7.36 | H6: =IFERROR(SUMIFS('Cleaned Data'!$C:$C,'Cleaned Data'!$A:$A,_xlfn.XLOOKUP($A6,Lookup!$A:$A,Lookup!$D:$D),'Cleaned Data'!$B:$B,H$3),"") -> 0.27 | I6: =IFERROR(SUMIFS('Cleaned Data'!$C:$C,'Cleaned Data'!$A:$A,_xlfn.XLOOKUP($A6,Lookup!$A:$A,Lookup!$D:$D),'Cleaned Data'!$B:$B,I$3),"") -> -0.18 | J6: =_xlfn.XLOOKUP($A6,Lookup!$A:$A,Lookup!$B:$B,"") -> EPS / Per Share | K6: =_xlfn.XLOOKUP($A6,Lookup!$A:$A,Lookup!$C:$C,"") -> Per Share
A7: =Lookup!A5 -> Distribution and Selling Expense | B7: =IFERROR(SUMIFS('Cleaned Data'!$C:$C,'Cleaned Data'!$A:$A,_xlfn.XLOOKUP($A7,Lookup!$A:$A,Lookup!$D:$D),'Cleaned Data'!$B:$B,B$3),"") -> -4029 | C7: =IFERROR(SUMIFS('Cleaned Data'!$C:$C,'Cleaned Data'!$A:$A,_xlfn.XLOOKUP($A7,Lookup!$A:$A,Lookup!$D:$D),'Cleaned Data'!$B:$B,C$3),"") -> -4710 | D7: =IFERROR(SUMIFS('Cleaned Data'!$C:$C,'Cleaned Data'!$A:$A,_xlfn.XLOOKUP($A7,Lookup!$A:$A,Lookup!$D:$D),'Cleaned Data'!$B:$B,D$3),"") -> -4909 | E7: =IFERROR(SUMIFS('Cleaned Data'!$C:$C,'Cleaned Data'!$A:$A,_xlfn.XLOOKUP($A7,Lookup!$A:$A,Lookup!$D:$D),'Cleaned Data'!$B:$B,E$3),"") -> -5272 | F7: =IFERROR(SUMIFS('Cleaned Data'!$C:$C,'Cleaned Data'!$A:$A,_xlfn.XLOOKUP($A7,Lookup!$A:$A,Lookup!$D:$D),'Cleaned Data'!$B:$B,F$3),"") -> -5358 | G7: =IFERROR(SUMIFS('Cleaned Data'!$C:$C,'Cleaned Data'!$A:$A,_xlfn.XLOOKUP($A7,Lookup!$A:$A,Lookup!$D:$D),'Cleaned Data'!$B:$B,G$3),"") -> -4969 | H7: =IFERROR(SUMIFS('Cleaned Data'!$C:$C,'Cleaned Data'!$A:$A,_xlfn.XLOOKUP($A7,Lookup!$A:$A,Lookup!$D:$D),'Cleaned Data'!$B:$B,H$3),"") -> -5470 | I7: =IFERROR(SUMIFS('Cleaned Data'!$C:$C,'Cleaned Data'!$A:$A,_xlfn.XLOOKUP($A7,Lookup!$A:$A,Lookup!$D:$D),'Cleaned Data'!$B:$B,I$3),"") -> -5528 | J7: =_xlfn.XLOOKUP($A7,Lookup!$A:$A,Lookup!$B:$B,"") -> Operating Expenses | K7: =_xlfn.XLOOKUP($A7,Lookup!$A:$A,Lookup!$C:$C,"") -> Negative
A8: =Lookup!A6 -> Dividend Per Share (DPS) | B8: =IFERROR(SUMIFS('Cleaned Data'!$C:$C,'Cleaned Data'!$A:$A,_xlfn.XLOOKUP($A8,Lookup!$A:$A,Lookup!$D:$D),'Cleaned Data'!$B:$B,B$3),"") -> 2 | C8: =IFERROR(SUMIFS('Cleaned Data'!$C:$C,'Cleaned Data'!$A:$A,_xlfn.XLOOKUP($A8,Lookup!$A:$A,Lookup!$D:$D),'Cleaned Data'!$B:$B,C$3),"") -> 2.6 | D8: =IFERROR(SUMIFS('Cleaned Data'!$C:$C,'Cleaned Data'!$A:$A,_xlfn.XLOOKUP($A8,Lookup!$A:$A,Lookup!$D:$D),'Cleaned Data'!$B:$B,D$3),"") -> 3.35 | E8: =IFERROR(SUMIFS('Cleaned Data'!$C:$C,'Cleaned Data'!$A:$A,_xlfn.XLOOKUP($A8,Lookup!$A:$A,Lookup!$D:$D),'Cleaned Data'!$B:$B,E$3),"") -> 3.85 | F8: =IFERROR(SUMIFS('Cleaned Data'!$C:$C,'Cleaned Data'!$A:$A,_xlfn.XLOOKUP($A8,Lookup!$A:$A,Lookup!$D:$D),'Cleaned Data'!$B:$B,F$3),"") -> 0 | G8: =IFERROR(SUMIFS('Cleaned Data'!$C:$C,'Cleaned Data'!$A:$A,_xlfn.XLOOKUP($A8,Lookup!$A:$A,Lookup!$D:$D),'Cleaned Data'!$B:$B,G$3),"") -> 3.3 | H8: =IFERROR(SUMIFS('Cleaned Data'!$C:$C,'Cleaned Data'!$A:$A,_xlfn.XLOOKUP($A8,Lookup!$A:$A,Lookup!$D:$D),'Cleaned Data'!$B:$B,H$3),"") -> 0.7 | I8: =IFERROR(SUMIFS('Cleaned Data'!$C:$C,'Cleaned Data'!$A:$A,_xlfn.XLOOKUP($A8,Lookup!$A:$A,Lookup!$D:$D),'Cleaned Data'!$B:$B,I$3),"") -> 0.7 | J8: =_xlfn.XLOOKUP($A8,Lookup!$A:$A,Lookup!$B:$B,"") -> EPS / Per Share | K8: =_xlfn.XLOOKUP($A8,Lookup!$A:$A,Lookup!$C:$C,"") -> Per Share
A9: =Lookup!A7 -> Effective Tax Rate % | B9: =IFERROR(SUMIFS('Cleaned Data'!$C:$C,'Cleaned Data'!$A:$A,_xlfn.XLOOKUP($A9,Lookup!$A:$A,Lookup!$D:$D),'Cleaned Data'!$B:$B,B$3),"") -> 0.29 | C9: =IFERROR(SUMIFS('Cleaned Data'!$C:$C,'Cleaned Data'!$A:$A,_xlfn.XLOOKUP($A9,Lookup!$A:$A,Lookup!$D:$D),'Cleaned Data'!$B:$B,C$3),"") -> 0.28 | D9: =IFERROR(SUMIFS('Cleaned Data'!$C:$C,'Cleaned Data'!$A:$A,_xlfn.XLOOKUP($A9,Lookup!$A:$A,Lookup!$D:$D),'Cleaned Data'!$B:$B,D$3),"") -> 0.26 | E9: =IFERROR(SUMIFS('Cleaned Data'!$C:$C,'Cleaned Data'!$A:$A,_xlfn.XLOOKUP($A9,Lookup!$A:$A,Lookup!$D:$D),'Cleaned Data'!$B:$B,E$3),"") -> 0.25 | F9: =IFERROR(SUMIFS('Cleaned Data'!$C:$C,'Cleaned Data'!$A:$A,_xlfn.XLOOKUP($A9,Lookup!$A:$A,Lookup!$D:$D),'Cleaned Data'!$B:$B,F$3),"") -> 0.35 | G9: =IFERROR(SUMIFS('Cleaned Data'!$C:$C,'Cleaned Data'!$A:$A,_xlfn.XLOOKUP($A9,Lookup!$A:$A,Lookup!$D:$D),'Cleaned Data'!$B:$B,G$3),"") -> 0.28 | H9: =IFERROR(SUMIFS('Cleaned Data'!$C:$C,'Cleaned Data'!$A:$A,_xlfn.XLOOKUP($A9,Lookup!$A:$A,Lookup!$D:$D),'Cleaned Data'!$B:$B,H$3),"") -> 0.75 | I9: =IFERROR(SUMIFS('Cleaned Data'!$C:$C,'Cleaned Data'!$A:$A,_xlfn.XLOOKUP($A9,Lookup!$A:$A,Lookup!$D:$D),'Cleaned Data'!$B:$B,I$3),"") -> 1.149 | J9: =_xlfn.XLOOKUP($A9,Lookup!$A:$A,Lookup!$B:$B,"") -> Below EBIT | K9: =_xlfn.XLOOKUP($A9,Lookup!$A:$A,Lookup!$C:$C,"") -> Percentage
A10: =Lookup!A8 -> Financial Expenses | B10: =IFERROR(SUMIFS('Cleaned Data'!$C:$C,'Cleaned Data'!$A:$A,_xlfn.XLOOKUP($A10,Lookup!$A:$A,Lookup!$D:$D),'Cleaned Data'!$B:$B,B$3),"") -> -74 | C10: =IFERROR(SUMIFS('Cleaned Data'!$C:$C,'Cleaned Data'!$A:$A,_xlfn.XLOOKUP($A10,Lookup!$A:$A,Lookup!$D:$D),'Cleaned Data'!$B:$B,C$3),"") -> -82 | D10: =IFERROR(SUMIFS('Cleaned Data'!$C:$C,'Cleaned Data'!$A:$A,_xlfn.XLOOKUP($A10,Lookup!$A:$A,Lookup!$D:$D),'Cleaned Data'!$B:$B,D$3),"") -> -91 | E10: =IFERROR(SUMIFS('Cleaned Data'!$C:$C,'Cleaned Data'!$A:$A,_xlfn.XLOOKUP($A10,Lookup!$A:$A,Lookup!$D:$D),'Cleaned Data'!$B:$B,E$3),"") -> -166 | F10: =IFERROR(SUMIFS('Cleaned Data'!$C:$C,'Cleaned Data'!$A:$A,_xlfn.XLOOKUP($A10,Lookup!$A:$A,Lookup!$D:$D),'Cleaned Data'!$B:$B,F$3),"") -> -178 | G10: =IFERROR(SUMIFS('Cleaned Data'!$C:$C,'Cleaned Data'!$A:$A,_xlfn.XLOOKUP($A10,Lookup!$A:$A,Lookup!$D:$D),'Cleaned Data'!$B:$B,G$3),"") -> -172 | H10: =IFERROR(SUMIFS('Cleaned Data'!$C:$C,'Cleaned Data'!$A:$A,_xlfn.XLOOKUP($A10,Lookup!$A:$A,Lookup!$D:$D),'Cleaned Data'!$B:$B,H$3),"") -> -199 | I10: =IFERROR(SUMIFS('Cleaned Data'!$C:$C,'Cleaned Data'!$A:$A,_xlfn.XLOOKUP($A10,Lookup!$A:$A,Lookup!$D:$D),'Cleaned Data'!$B:$B,I$3),"") -> -242 | J10: =_xlfn.XLOOKUP($A10,Lookup!$A:$A,Lookup!$B:$B,"") -> Below EBIT | K10: =_xlfn.XLOOKUP($A10,Lookup!$A:$A,Lookup!$C:$C,"") -> Negative
A11: =Lookup!A9 -> Financial Income | B11: =IFERROR(SUMIFS('Cleaned Data'!$C:$C,'Cleaned Data'!$A:$A,_xlfn.XLOOKUP($A11,Lookup!$A:$A,Lookup!$D:$D),'Cleaned Data'!$B:$B,B$3),"") -> 20 | C11: =IFERROR(SUMIFS('Cleaned Data'!$C:$C,'Cleaned Data'!$A:$A,_xlfn.XLOOKUP($A11,Lookup!$A:$A,Lookup!$D:$D),'Cleaned Data'!$B:$B,C$3),"") -> 24 | D11: =IFERROR(SUMIFS('Cleaned Data'!$C:$C,'Cleaned Data'!$A:$A,_xlfn.XLOOKUP($A11,Lookup!$A:$A,Lookup!$D:$D),'Cleaned Data'!$B:$B,D$3),"") -> 28 | E11: =IFERROR(SUMIFS('Cleaned Data'!$C:$C,'Cleaned Data'!$A:$A,_xlfn.XLOOKUP($A11,Lookup!$A:$A,Lookup!$D:$D),'Cleaned Data'!$B:$B,E$3),"") -> 32 | F11: =IFERROR(SUMIFS('Cleaned Data'!$C:$C,'Cleaned Data'!$A:$A,_xlfn.XLOOKUP($A11,Lookup!$A:$A,Lookup!$D:$D),'Cleaned Data'!$B:$B,F$3),"") -> 26 | G11: =IFERROR(SUMIFS('Cleaned Data'!$C:$C,'Cleaned Data'!$A:$A,_xlfn.XLOOKUP($A11,Lookup!$A:$A,Lookup!$D:$D),'Cleaned Data'!$B:$B,G$3),"") -> 30 | H11: =IFERROR(SUMIFS('Cleaned Data'!$C:$C,'Cleaned Data'!$A:$A,_xlfn.XLOOKUP($A11,Lookup!$A:$A,Lookup!$D:$D),'Cleaned Data'!$B:$B,H$3),"") -> 44 | I11: =IFERROR(SUMIFS('Cleaned Data'!$C:$C,'Cleaned Data'!$A:$A,_xlfn.XLOOKUP($A11,Lookup!$A:$A,Lookup!$D:$D),'Cleaned Data'!$B:$B,I$3),"") -> 62 | J11: =_xlfn.XLOOKUP($A11,Lookup!$A:$A,Lookup!$B:$B,"") -> Below EBIT | K11: =_xlfn.XLOOKUP($A11,Lookup!$A:$A,Lookup!$C:$C,"") -> Positive
A12: =Lookup!A10 -> GROSS PROFIT | B12: =IFERROR(SUMIFS('Cleaned Data'!$C:$C,'Cleaned Data'!$A:$A,_xlfn.XLOOKUP($A12,Lookup!$A:$A,Lookup!$D:$D),'Cleaned Data'!$B:$B,B$3),"") -> 8983 | C12: =IFERROR(SUMIFS('Cleaned Data'!$C:$C,'Cleaned Data'!$A:$A,_xlfn.XLOOKUP($A12,Lookup!$A:$A,Lookup!$D:$D),'Cleaned Data'!$B:$B,C$3),"") -> 10694 | D12: =IFERROR(SUMIFS('Cleaned Data'!$C:$C,'Cleaned Data'!$A:$A,_xlfn.XLOOKUP($A12,Lookup!$A:$A,Lookup!$D:$D),'Cleaned Data'!$B:$B,D$3),"") -> 11308 | E12: =IFERROR(SUMIFS('Cleaned Data'!$C:$C,'Cleaned Data'!$A:$A,_xlfn.XLOOKUP($A12,Lookup!$A:$A,Lookup!$D:$D),'Cleaned Data'!$B:$B,E$3),"") -> 12293 | F12: =IFERROR(SUMIFS('Cleaned Data'!$C:$C,'Cleaned Data'!$A:$A,_xlfn.XLOOKUP($A12,Lookup!$A:$A,Lookup!$D:$D),'Cleaned Data'!$B:$B,F$3),"") -> 9862 | G12: =IFERROR(SUMIFS('Cleaned Data'!$C:$C,'Cleaned Data'!$A:$A,_xlfn.XLOOKUP($A12,Lookup!$A:$A,Lookup!$D:$D),'Cleaned Data'!$B:$B,G$3),"") -> 10723 | H12: =IFERROR(SUMIFS('Cleaned Data'!$C:$C,'Cleaned Data'!$A:$A,_xlfn.XLOOKUP($A12,Lookup!$A:$A,Lookup!$D:$D),'Cleaned Data'!$B:$B,H$3),"") -> 10648 | I12: =IFERROR(SUMIFS('Cleaned Data'!$C:$C,'Cleaned Data'!$A:$A,_xlfn.XLOOKUP($A12,Lookup!$A:$A,Lookup!$D:$D),'Cleaned Data'!$B:$B,I$3),"") -> 10178 | J12: =_xlfn.XLOOKUP($A12,Lookup!$A:$A,Lookup!$B:$B,"") -> Gross Profit | K12: =_xlfn.XLOOKUP($A12,Lookup!$A:$A,Lookup!$C:$C,"") -> Positive
A13: =Lookup!A11 -> General & Administration | B13: =IFERROR(SUMIFS('Cleaned Data'!$C:$C,'Cleaned Data'!$A:$A,_xlfn.XLOOKUP($A13,Lookup!$A:$A,Lookup!$D:$D),'Cleaned Data'!$B:$B,B$3),"") -> -998 | C13: =IFERROR(SUMIFS('Cleaned Data'!$C:$C,'Cleaned Data'!$A:$A,_xlfn.XLOOKUP($A13,Lookup!$A:$A,Lookup!$D:$D),'Cleaned Data'!$B:$B,C$3),"") -> -1125 | D13: =IFERROR(SUMIFS('Cleaned Data'!$C:$C,'Cleaned Data'!$A:$A,_xlfn.XLOOKUP($A13,Lookup!$A:$A,Lookup!$D:$D),'Cleaned Data'!$B:$B,D$3),"") -> -1140 | E13: =IFERROR(SUMIFS('Cleaned Data'!$C:$C,'Cleaned Data'!$A:$A,_xlfn.XLOOKUP($A13,Lookup!$A:$A,Lookup!$D:$D),'Cleaned Data'!$B:$B,E$3),"") -> -1347 | F13: =IFERROR(SUMIFS('Cleaned Data'!$C:$C,'Cleaned Data'!$A:$A,_xlfn.XLOOKUP($A13,Lookup!$A:$A,Lookup!$D:$D),'Cleaned Data'!$B:$B,F$3),"") -> -1290 | G13: =IFERROR(SUMIFS('Cleaned Data'!$C:$C,'Cleaned Data'!$A:$A,_xlfn.XLOOKUP($A13,Lookup!$A:$A,Lookup!$D:$D),'Cleaned Data'!$B:$B,G$3),"") -> -1295 | H13: =IFERROR(SUMIFS('Cleaned Data'!$C:$C,'Cleaned Data'!$A:$A,_xlfn.XLOOKUP($A13,Lookup!$A:$A,Lookup!$D:$D),'Cleaned Data'!$B:$B,H$3),"") -> -1756 | I13: =IFERROR(SUMIFS('Cleaned Data'!$C:$C,'Cleaned Data'!$A:$A,_xlfn.XLOOKUP($A13,Lookup!$A:$A,Lookup!$D:$D),'Cleaned Data'!$B:$B,I$3),"") -> -1564 | J13: =_xlfn.XLOOKUP($A13,Lookup!$A:$A,Lookup!$B:$B,"") -> Operating Expenses | K13: =_xlfn.XLOOKUP($A13,Lookup!$A:$A,Lookup!$C:$C,"") -> Negative
A14: =Lookup!A12 -> Goodwill / Intangible Impairment | B14: =IFERROR(SUMIFS('Cleaned Data'!$C:$C,'Cleaned Data'!$A:$A,_xlfn.XLOOKUP($A14,Lookup!$A:$A,Lookup!$D:$D),'Cleaned Data'!$B:$B,B$3),"") -> 0 | C14: =IFERROR(SUMIFS('Cleaned Data'!$C:$C,'Cleaned Data'!$A:$A,_xlfn.XLOOKUP($A14,Lookup!$A:$A,Lookup!$D:$D),'Cleaned Data'!$B:$B,C$3),"") -> 0 | D14: =IFERROR(SUMIFS('Cleaned Data'!$C:$C,'Cleaned Data'!$A:$A,_xlfn.XLOOKUP($A14,Lookup!$A:$A,Lookup!$D:$D),'Cleaned Data'!$B:$B,D$3),"") -> 0 | E14: =IFERROR(SUMIFS('Cleaned Data'!$C:$C,'Cleaned Data'!$A:$A,_xlfn.XLOOKUP($A14,Lookup!$A:$A,Lookup!$D:$D),'Cleaned Data'!$B:$B,E$3),"") -> 0 | F14: =IFERROR(SUMIFS('Cleaned Data'!$C:$C,'Cleaned Data'!$A:$A,_xlfn.XLOOKUP($A14,Lookup!$A:$A,Lookup!$D:$D),'Cleaned Data'!$B:$B,F$3),"") -> 0 | G14: =IFERROR(SUMIFS('Cleaned Data'!$C:$C,'Cleaned Data'!$A:$A,_xlfn.XLOOKUP($A14,Lookup!$A:$A,Lookup!$D:$D),'Cleaned Data'!$B:$B,G$3),"") -> 0 | H14: =IFERROR(SUMIFS('Cleaned Data'!$C:$C,'Cleaned Data'!$A:$A,_xlfn.XLOOKUP($A14,Lookup!$A:$A,Lookup!$D:$D),'Cleaned Data'!$B:$B,H$3),"") -> -194 | I14: =IFERROR(SUMIFS('Cleaned Data'!$C:$C,'Cleaned Data'!$A:$A,_xlfn.XLOOKUP($A14,Lookup!$A:$A,Lookup!$D:$D),'Cleaned Data'!$B:$B,I$3),"") -> 0 | J14: =_xlfn.XLOOKUP($A14,Lookup!$A:$A,Lookup!$B:$B,"") -> Operating Expenses | K14: =_xlfn.XLOOKUP($A14,Lookup!$A:$A,Lookup!$C:$C,"") -> Negative
A15: =Lookup!A13 -> Gross Margin % | B15: =IFERROR(SUMIFS('Cleaned Data'!$C:$C,'Cleaned Data'!$A:$A,_xlfn.XLOOKUP($A15,Lookup!$A:$A,Lookup!$D:$D),'Cleaned Data'!$B:$B,B$3),"") -> 0.486 | C15: =IFERROR(SUMIFS('Cleaned Data'!$C:$C,'Cleaned Data'!$A:$A,_xlfn.XLOOKUP($A15,Lookup!$A:$A,Lookup!$D:$D),'Cleaned Data'!$B:$B,C$3),"") -> 0.504 | D15: =IFERROR(SUMIFS('Cleaned Data'!$C:$C,'Cleaned Data'!$A:$A,_xlfn.XLOOKUP($A15,Lookup!$A:$A,Lookup!$D:$D),'Cleaned Data'!$B:$B,D$3),"") -> 0.516 | E15: =IFERROR(SUMIFS('Cleaned Data'!$C:$C,'Cleaned Data'!$A:$A,_xlfn.XLOOKUP($A15,Lookup!$A:$A,Lookup!$D:$D),'Cleaned Data'!$B:$B,E$3),"") -> 0.52 | F15: =IFERROR(SUMIFS('Cleaned Data'!$C:$C,'Cleaned Data'!$A:$A,_xlfn.XLOOKUP($A15,Lookup!$A:$A,Lookup!$D:$D),'Cleaned Data'!$B:$B,F$3),"") -> 0.497 | G15: =IFERROR(SUMIFS('Cleaned Data'!$C:$C,'Cleaned Data'!$A:$A,_xlfn.XLOOKUP($A15,Lookup!$A:$A,Lookup!$D:$D),'Cleaned Data'!$B:$B,G$3),"") -> 0.505 | H15: =IFERROR(SUMIFS('Cleaned Data'!$C:$C,'Cleaned Data'!$A:$A,_xlfn.XLOOKUP($A15,Lookup!$A:$A,Lookup!$D:$D),'Cleaned Data'!$B:$B,H$3),"") -> 0.473 | I15: =IFERROR(SUMIFS('Cleaned Data'!$C:$C,'Cleaned Data'!$A:$A,_xlfn.XLOOKUP($A15,Lookup!$A:$A,Lookup!$D:$D),'Cleaned Data'!$B:$B,I$3),"") -> 0.475 | J15: =_xlfn.XLOOKUP($A15,Lookup!$A:$A,Lookup!$B:$B,"") -> Margin | K15: =_xlfn.XLOOKUP($A15,Lookup!$A:$A,Lookup!$C:$C,"") -> Percentage
... A36: =Lookup!A34 -> Wtd. Avg Shares - Diluted (mn) | B36: =IFERROR(SUMIFS('Cleaned Data'!$C:$C,'Cleaned Data'!$A:$A,_xlfn.XLOOKUP($A36,Lookup!$A:$A,Lookup!$D:$D),'Cleaned Data'!$B:$B,B$3),"") -> 201.8 | C36: =IFERROR(SUMIFS('Cleaned Data'!$C:$C,'Cleaned Data'!$A:$A,_xlfn.XLOOKUP($A36,Lookup!$A:$A,Lookup!$D:$D),'Cleaned Data'!$B:$B,C$3),"") -> 203.3 | D36: =IFERROR(SUMIFS('Cleaned Data'!$C:$C,'Cleaned Data'!$A:$A,_xlfn.XLOOKUP($A36,Lookup!$A:$A,Lookup!$D:$D),'Cleaned Data'!$B:$B,D$3),"") -> 200.8 | E36: =IFERROR(SUMIFS('Cleaned Data'!$C:$C,'Cleaned Data'!$A:$A,_xlfn.XLOOKUP($A36,Lookup!$A:$A,Lookup!$D:$D),'Cleaned Data'!$B:$B,E$3),"") -> 196.5 | F36: =IFERROR(SUMIFS('Cleaned Data'!$C:$C,'Cleaned Data'!$A:$A,_xlfn.XLOOKUP($A36,Lookup!$A:$A,Lookup!$D:$D),'Cleaned Data'!$B:$B,F$3),"") -> 195.1 | G36: =IFERROR(SUMIFS('Cleaned Data'!$C:$C,'Cleaned Data'!$A:$A,_xlfn.XLOOKUP($A36,Lookup!$A:$A,Lookup!$D:$D),'Cleaned Data'!$B:$B,G$3),"") -> 196.6 | H36: =IFERROR(SUMIFS('Cleaned Data'!$C:$C,'Cleaned Data'!$A:$A,_xlfn.XLOOKUP($A36,Lookup!$A:$A,Lookup!$D:$D),'Cleaned Data'!$B:$B,H$3),"") -> 184.2 | I36: =IFERROR(SUMIFS('Cleaned Data'!$C:$C,'Cleaned Data'!$A:$A,_xlfn.XLOOKUP($A36,Lookup!$A:$A,Lookup!$D:$D),'Cleaned Data'!$B:$B,I$3),"") -> 179.3 | J36: =_xlfn.XLOOKUP($A36,Lookup!$A:$A,Lookup!$B:$B,"") -> Share Data | K36: =_xlfn.XLOOKUP($A36,Lookup!$A:$A,Lookup!$C:$C,"") -> Shares
A39: Revenue YoY Growth | B39: FY2016 | C39: FY2017 | D39: FY2018 | E39: FY2019 | F39: FY2020 | G39: FY2021 | H39: FY2022 | I39: FY2023
C40: =(C32-B32)/B32 -> 0.14797381 | D40: =(D32-C32)/C32 -> 0.032849467 | E40: =(E32-D32)/D32 -> 0.07871321 | F40: =(F32-E32)/E32 -> -0.1605753 | G40: =(G32-F32)/F32 -> 0.070046362 | H40: =(H32-G32)/G32 -> 0.060139399 | I40: =(I32-H32)/H32 -> -0.048154236
A41: Gross Profit YoY Growth | B41: FY2016 | C41: FY2017 | D41: FY2018 | E41: FY2019 | F41: FY2020 | G41: FY2021 | H41: FY2022 | I41: FY2023
C42: =(C12-B12)/B12 -> 0.19047089 | D42: =(D12-C12)/C12 -> 0.057415373 | E42: =(E12-D12)/D12 -> 0.087106473 | F42: =(F12-E12)/E12 -> -0.19775482 | G42: =(G12-F12)/F12 -> 0.087304806 | H42: =(H12-G12)/G12 -> -0.0069943113 | I42: =(I12-H12)/H12 -> -0.044139745
A43: Operating Profit YoY Growth | B43: FY2016 | C43: FY2017 | D43: FY2018 | E43: FY2019 | F43: FY2020 | G43: FY2021 | H43: FY2022 | I43: FY2023
C44: =(C24-B24)/B24 -> 0.41080313 | D44: =(D24-C24)/C24 -> 0.18942065 | E44: =(E24-D24)/D24 -> 0.10969928 | F44: =(F24-E24)/E24 -> -0.69351145 | G44: =(G24-F24)/F24 -> 1.2914072 | H44: =(H24-G24)/G24 -> -0.78967391 | I44: =(I24-H24)/H24 -> -0.082687339
A45: Net Income YoY Growth | B45: FY2016 | C45: FY2017 | D45: FY2018 | E45: FY2019 | F45: FY2020 | G45: FY2021 | H45: FY2022 | I45: FY2023
C46: =(C21-B21)/B21 -> 0.44328824 | D46: =(D21-C21)/C21 -> 0.22638789 | E46: =(E21-D21)/D21 -> 0.095825985 | F46: =(F21-E21)/E21 -> -0.81062232 | G46: =(G21-F21)/F21 -> 3.121813 | H46: =(H21-G21)/G21 -> -0.96013746 | I46: =(I21-H21)/H21 -> -1.4482759
A47: Revenue CAGR | B47: FY2016 | C47: FY2017 | D47: FY2018 | E47: FY2019 | F47: FY2020 | G47: FY2021 | H47: FY2022 | I47: FY2023
B48: =(I32/B32)^(1/7)-1 -> 0.02133883
A49: Net Income CAGR | B49: FY2016 | C49: FY2017 | D49: FY2018 | E49: FY2019 | F49: FY2020 | G49: FY2021 | H49: FY2022 | I49: FY2023
B50: N/A | C50: Not meaningful because FY2023 Net Income is negative
A52: Revenue Index | B52: 100 | C52: =(C32/$B32)*100 -> 114.79738 | D52: =(D32/$B32)*100 -> 118.56841 | E52: =(E32/$B32)*100 -> 127.90131 | F52: =(F32/$B32)*100 -> 107.36352 | G52: =(G32/$B32)*100 -> 114.88395 | H52: =(H32/$B32)*100 -> 121.793 | I52: =(I32/$B32)*100 -> 115.92815
A53: Gross Profit Index | B53: 100 | C53: =(C12/$B12)*100 -> 119.04709 | D53: =(D12/$B12)*100 -> 125.88222 | E53: =(E12/$B12)*100 -> 136.84738 | F53: =(F12/$B12)*100 -> 109.78515 | G53: =(G12/$B12)*100 -> 119.36992 | H53: =(H12/$B12)*100 -> 118.53501 | I53: =(I12/$B12)*100 -> 113.30291
A54: Total Operating Expenses Index | B54: 100 | C54: =(C33/$B33)*100 -> 114.79855 | D54: =(D33/$B33)*100 -> 118.01395 | E54: =(E33/$B33)*100 -> 127.59556 | F54: =(F33/$B33)*100 -> 118.89205 | G54: =(G33/$B33)*100 -> 116.8001 | H54: =(H33/$B33)*100 -> 132.25723 | I54: =(I33/$B33)*100 -> 128.93853
A56: Revenue vs Operating Expense Growth
A57: Operating Expense % of Revenue | B57: =ABS(B33)/B32 -> 0.4189796 | C57: =ABS(C33)/C32 -> 0.41898388 | D57: =ABS(D33)/D32 -> 0.41702031 | E57: =ABS(E33)/E32 -> 0.417978 | F57: =ABS(F33)/F32 -> 0.46396896 | G57: =ABS(G33)/G32 -> 0.42596779 | H57: =ABS(H33)/H32 -> 0.45497757 | I57: =ABS(I33)/I32 -> 0.46600084
A58: Operating Expense YoY Growth | C58: =(ABS(C33)-ABS(B33))/ABS(B33) -> 0.14798554 | D58: =(ABS(D33)-ABS(C33))/ABS(C33) -> 0.028008999 | E58: =(ABS(E33)-ABS(D33))/ABS(D33) -> 0.081190502 | F58: =(ABS(F33)-ABS(E33))/ABS(E33) -> -0.068211719 | G58: =(ABS(G33)-ABS(F33))/ABS(F33) -> -0.017595308 | H58: =(ABS(H33)-ABS(G33))/ABS(G33) -> 0.13233831 | I58: =(ABS(I33)-ABS(H33))/ABS(H33) -> -0.025092755
A60: Gross Margin % | B60: =B15 -> 0.486 | C60: =C15 -> 0.504 | D60: =D15 -> 0.516 | E60: =E15 -> 0.52 | F60: =F15 -> 0.497 | G60: =G15 -> 0.505 | H60: =H15 -> 0.473 | I60: =I15 -> 0.475
A61: Operating Margin % | B61: =B25 -> 0.076 | C61: =C25 -> 0.094 | D61: =D25 -> 0.108 | E61: =E25 -> 0.111 | F61: =F25 -> 0.04 | G61: =G25 -> 0.087 | H61: =H25 -> 0.017 | I61: =I25 -> 0.017
A62: Net Margin % | B62: =B20/B32 -> 0.051344479 | C62: =C20/C32 -> 0.064709209 | D62: =D20/D32 -> 0.077116131 | E62: =E20/E32 -> 0.078468697 | F62: =F20/F32 -> 0.017486394 | G62: =G20/G32 -> 0.068145427 | H62: =H20/H32 -> 0.0022211363 | I62: =I20/I32 -> -0.0015401129
A64: Revenue — Best / Worst Year | B64: ="Best: "&INDEX($B$3:$I$3,MATCH(MAX($B$32:$I$32),$B$32:$I$32,0))&" | Worst: "&INDEX($B$3:$I$3,MATCH(MIN($B$32:$I$32),$B$32:$I$32,0)) -> Best: FY2019 | Worst: FY2016
A65: Operating Profit — Best / Worst Year | B65: ="Best: "&INDEX($B$3:$I$3,MATCH(MAX($B$24:$I$24),$B$24:$I$24,0))&" | Worst: "&INDEX($B$3:$I$3,MATCH(MIN($B$24:$I$24),$B$24:$I$24,0)) -> Best: FY2019 | Worst: FY2023
A66: EPS — Best / Worst Year | B66: ="Best: "&INDEX($B$3:$I$3,MATCH(MAX($B$4:$I$4),$B$4:$I$4,0))&" | Worst: "&INDEX($B$3:$I$3,MATCH(MIN($B$4:$I$4),$B$4:$I$4,0)) -> Best: FY2019 | Worst: FY2023
...

Sheet Summary
A1: Bloomberg P&L Analysis — Executive Summary
A2: ADS GY Equity | FY2016–FY2023 | EUR mn unless stated
A4: KEY PERFORMANCE INDICATORS
A5: FY2023 Revenue | B5: ='Master P&L'!I32 -> 21427 | C5: FY2023 Operating Margin | D5: ='Master P&L'!I61 -> 0.017 | E5: FY2023 Net Margin | F5: ='Master P&L'!I62 -> -0.0015401129 | G5: Revenue CAGR | H5: ='Master P&L'!B48 -> 0.02133883
A7: PERFORMANCE SNAPSHOT
A8: FY2016 Revenue | B8: ='Master P&L'!B32 -> 18483 | C8: FY2023 Revenue | D8: ='Master P&L'!I32 -> 21427 | E8: Revenue Change | F8: =D8-B8 -> 2944 | G8: Revenue CAGR | H8: ='Master P&L'!B48 -> 0.02133883
A10: PROFITABILITY SNAPSHOT
A11: FY2019 Operating Margin | B11: ='Master P&L'!E61 -> 0.111 | C11: FY2023 Operating Margin | D11: ='Master P&L'!I61 -> 0.017 | E11: Operating Margin Change | F11: ='Master P&L'!B70 -> -0.094 | G11: FY2023 Net Margin | H11: ='Master P&L'!I62 -> -0.0015401129
A13: REVENUE MIX
A14: FY2016 Retail Share | B14: ='Master P&L'!B84 -> 0.31602013 | C14: FY2023 Retail Share | D14: ='Master P&L'!C84 -> 0.45297989 | E14: FY2016 Wholesale Share | F14: ='Master P&L'!B85 -> 0.63101228 | G14: FY2023 Wholesale Share | H14: ='Master P&L'!C85 -> 0.51999813
A16: KEY INSIGHTS
A17: Peak Revenue Year | B17: ='Master P&L'!B64 -> Best: FY2019 | Worst: FY2016 | C17: Operating Profit Best Year | D17: ='Master P&L'!B65 -> Best: FY2019 | Worst: FY2023 | E17: Best EPS Year | F17: ='Master P&L'!B66 -> Best: FY2019 | Worst: FY2023 | G17: Tax Rate >100% Year | H17: ='Master P&L'!B77 -> FY2023
A19: FY2022–FY2023 Weakness
A20: Operating Profit | B20: 355 → 355 | C20: Operating margin remained ~1.7%
A21: Income Before Taxes | B21: 232 → 175 | C21: Lower due to higher net financial expense
A22: Income Tax Expense | B22: -174 → -201 | C22: Higher tax expense further reduced net inco
A23: Net Income | B23: 58 → -26 | C23: Net income turned negative in FY2023
A24: Overall Explanation | B24: Below-EBIT items drove the FY2023 net-margin decline
A26: REVENUE MIX CHANGE
A27: REVENUE MIX CHANGE | B27: 31.60% → 45.30% | C27: +13.70 pp
A28: Wholesale Share Change | B28: 63.10% → 52.00% | C28: -11.10 pp
A29: Retail Revenue Growth | B29: 0.6616
A30: Wholesale Revenue Growth | B30: -0.0448
A32: OPERATING EXPENSE INSIGHT
A33: FY2023 Operating Expense / Revenue | B33: 0.466
A34: Largest Share Increase | B34: Distribution and selling | C34: 21.8% → 25.8%
A35: Impairment | B35: FY2022 | C35: €194m goodwill/intangible impairment
A37: BRAND DISCLOSURE
A38: Reebok was divested effective FY2022; brand-level revenue is not reported thereafter.
A40: EXECUTIVE TAKEAWAYS
A41: Revenue grew modestly over FY2016–FY2023, with 2.13% CAGR.
A42: FY2019 was the peak profitability year, while FY2023 ended with negative net income.
A43: Retail increased its revenue mix while wholesale share declined.
A44: Operating expenses reached 46.6% of revenue in FY2023, limiting operating margin.
A45: FY2023 net margin was further pressured by below-EBIT items and higher tax expense.

Sheet Cleaned Data
A1: Line Item | B1: Fiscal Year | C1: Value
A2: Wholesale | B2: FY2016 | C2: 11663
A3: Retail | B3: FY2016 | C3: 5841
A4: Other Businesses | B4: FY2016 | C4: 979
A5: Total Net Revenue | B5: FY2016 | C5: 18483
A6: Cost of Goods Sold | B6: FY2016 | C6: -9500
A7: GROSS PROFIT | B7: FY2016 | C7: 8983
A8: Gross Margin % | B8: FY2016 | C8: 0.486
A9: Royalty and Commission Income | B9: FY2016 | C9: 108
A10: Other Operating Income | B10: FY2016 | C10: 60
A11: Marketing and Point-of-Sale | B11: FY2016 | C11: -2532
A12: Distribution and Selling Expense | B12: FY2016 | C12: -4029
A13: General & Administration | B13: FY2016 | C13: -998
... A250: Dividend Per Share (DPS) | B250: FY2023 | C250: 0.7

Sheet Lookup
A1: Line Item | B1: Statement Group | C1: Sign Conversion | D1: Source Line Item
A2: Basic EPS | B2: EPS / Per Share | C2: Per Share | D2: Basic EPS
A3: Cost of Goods Sold | B3: COGS | C3: Negative | D3: Cost of Goods Sold
A4: Diluted EPS | B4: EPS / Per Share | C4: Per Share | D4: Diluted EPS
A5: Distribution and Selling Expense | B5: Operating Expenses | C5: Negative | D5: Distribution and Selling Expense
A6: Dividend Per Share (DPS) | B6: EPS / Per Share | C6: Per Share | D6: Dividend Per Share (DPS)
A7: Effective Tax Rate % | B7: Below EBIT | C7: Percentage | D7: Effective Tax Rate %
A8: Financial Expenses | B8: Below EBIT | C8: Negative | D8: Financial Expenses
A9: Financial Income | B9: Below EBIT | C9: Positive | D9: Financial Income
A10: GROSS PROFIT | B10: Gross Profit | C10: Positive | D10: GROSS PROFIT
A11: General & Administration | B11: Operating Expenses | C11: Negative | D11: General & Administration
A12: Goodwill / Intangible Impairment | B12: Operating Expenses | C12: Negative | D12: Goodwill / Intangible Impairment
... A34: Wtd. Avg Shares - Diluted (mn) | B34: Share Data | C34: Shares | D34: Wtd. Avg Shares - Diluted (mn)
A37: Raw Region | B37: Comparable Region
A38: Western Europe | B38: EMEA
A39: Emerging Markets | B39: EMEA
A40: North America | B40: North America
A41: Grtr China | B41: Greater China
A42: Other Asian Mkts | B42: Asia-Pacific
A43: Russia / CIS | B43: Asia-Pacific
A44: Latin America | B44: Latin America
A45: Other Businesses | B45: Other Businesses

Sheet Comparable Regional View
A1: Comparable Regional Revenue (EUR mn)
A3: Region | B3: FY2016 | C3: FY2017 | D3: FY2018 | E3: FY2019 | F3: FY2020 | G3: FY2021 | H3: FY2022 | I3: FY2023
A4: EMEA | B4: ='REV BY GEO'!C7+'REV BY GEO'!C10+'REV BY GEO'!C13 -> 7393 | C4: ='REV BY GEO'!D7+'REV BY GEO'!D10+'REV BY GEO'!D13 -> 7956 | D4: ='REV BY GEO'!E7+'REV BY GEO'!E10+'REV BY GEO'!E13 -> 7955 | E4: ='REV BY GEO'!F7+'REV BY GEO'!F10+'REV BY GEO'!F13 -> 8369 | F4: =VALUE('REV BY GEO'!G17) -> 7005 | G4: =VALUE('REV BY GEO'!H17) -> 7432 | H4: =VALUE('REV BY GEO'!I17) -> 7879 | I4: =VALUE('REV BY GEO'!J17) -> 7585
A5: North America | B5: ='REV BY GEO'!C8 -> 3,068.0 | C5: ='REV BY GEO'!D8 -> 3,947.0 | D5: ='REV BY GEO'!E8 -> 4,361.0 | E5: ='REV BY GEO'!F8 -> 4,917.0 | F5: =VALUE('REV BY GEO'!G18) -> 4127 | G5: =VALUE('REV BY GEO'!H18) -> 5330 | H5: =VALUE('REV BY GEO'!I18) -> 5921 | I5: =VALUE('REV BY GEO'!J18) -> 5142
A6: Greater China | B6: ='REV BY GEO'!C9 -> 2,976.0 | C6: ='REV BY GEO'!D9 -> 3,756.0 | D6: ='REV BY GEO'!E9 -> 4,164.0 | E6: ='REV BY GEO'!F9 -> 4,728.0 | F6: =VALUE('REV BY GEO'!G19) -> 4346 | G6: =VALUE('REV BY GEO'!H19) -> 4247 | H6: =VALUE('REV BY GEO'!I19) -> 3534 | I6: =VALUE('REV BY GEO'!J19) -> 3257
A7: Asia-Pacific | B7: 2421 | C7: 2716 | D7: 2761 | E7: 2931 | F7: 2342 | G7: 2060 | H7: 2656 | I7: 2807
A8: Latin America | B8: ='REV BY GEO'!C11 -> 1,645.0 | C8: ='REV BY GEO'!D11 -> 1,740.0 | D8: ='REV BY GEO'!E11 -> 1,688.0 | E8: ='REV BY GEO'!F11 -> 1,726.0 | F8: =VALUE('REV BY GEO'!G21) -> 1310 | G8: =VALUE('REV BY GEO'!H21) -> 1507 | H8: =VALUE('REV BY GEO'!I21) -> 1891 | I8: =VALUE('REV BY GEO'!J21) -> 2057
A9: Other Businesses | B9: ='REV BY GEO'!C14 -> 980.0 | C9: ='REV BY GEO'!D14 -> 1,103.0 | D9: ='REV BY GEO'!E14 -> 986.0 | E9: ='REV BY GEO'!F14 -> 969.0 | F9: =VALUE('REV BY GEO'!G22) -> 714 | G9: =VALUE('REV BY GEO'!H22) -> 658 | H9: =VALUE('REV BY GEO'!I22) -> 630 | I9: =VALUE('REV BY GEO'!J22) -> 579
A11: FY2016–FY2023 Growth %
A12: EMEA | B12: =(I4/B4)-1 -> 0.025970513
A13: North America | B13: =(I5/B5)-1 -> 0.67601043
A14: Greater China | B14: =(I6/B6)-1 -> 0.094422043
A15: Asia-Pacific | B15: =(I7/B7)-1 -> 0.15943825
A16: Latin America | B16: =(I8/B8)-1 -> 0.25045593
A17: Other Businesses | B17: =(I9/B9)-1 -> -0.40918367
A19: FY2019–FY2023 Revenue Change (EUR mn)
A20: EMEA | B20: =I4-E4 -> -784
A21: North America | B21: =I5-E5 -> 225
A22: Greater China | B22: =I6-E6 -> -1471
A23: Asia-Pacific | B23: =I7-E7 -> -124
A24: Latin America | B24: =I8-E8 -> 331
A25: Other Businesses | B25: =I9-E9 -> -390
A27: FY2019–FY2023 Contribution to Total Revenue Change
A28: EMEA | B28: =B20/SUM($B$20:$B$25) -> 0.35427022
A29: North America | B29: =B21/SUM($B$20:$B$25) -> -0.10167194
A30: Greater China | B30: =B22/SUM($B$20:$B$25) -> 0.66470854
A31: Asia-Pacific | B31: 0.0439
A32: Latin America | B32: =B24/SUM($B$20:$B$25) -> -0.14957072
A33: Other Businesses | B33: =B25/SUM($B$20:$B$25) -> 0.17623136

Sheet Raw Region Data 
A3: Western Europe | C3: 5452 | D3: 5856 | E3: 5764 | F3: 5957
A4: North America | C4: 3068 | D4: 3947 | E4: 4361 | F4: 4917
A5: Grtr China | C5: 2976 | D5: 3756 | E5: 4164 | F5: 4728
A6: Russia / CIS | C6: 721 | D6: 700 | E6: 679 | F6: 686
A7: Latin America | C7: 1645 | D7: 1740 | E7: 1688 | F7: 1726
A8: Other Asian Mkts | C8: 2421 | D8: 2716 | E8: 2761 | F8: 2931
A9: Emerging Markets | C9: 1220 | D9: 1400 | E9: 1512 | F9: 1726
A10: Other Businesses | C10: 980 | D10: 1103 | E10: 986 | F10: 969
